Workbook

Sheet Ratios
B2: Investor Ratio
B3: Earnings per Share (EPS) | C3: =ROUND(SOPL!C24/500000 * 100, 1)&" cents" -> 21.9 cents
B6: Profitability Ratios
B7: Gross Profit Margin (GPM) | C7: =SOPL!C8/SUM(SOPL!C4:C5) -> 0.42181467
B8: Operating Profit Margin (OPM) | C8: =SOPL!C18/SUM(SOPL!C4:C5) -> 0.2997426
B9: Return on Capital Employed (ROCE) | C9: =SOPL!C20/SUM(SOFP!D17,SOFP!D20) -> 0.20476525
B12: Efficiency Ratios
B13: Net Asset Turnover | C13: =ROUND(SUM(SOPL!C4:C5)/SUM(SOFP!D17:D20), 2)& " times" -> 0.68 times
B14: Inventory Days | C14: =ROUND(31 * SOFP!C7/(298000), 0)&" days" -> 8 days
B15: Receivable Days | C15: =ROUND(31 * SOFP!C8/395000, 0)&" days" -> 18 days
B16: Payable Days | C16: =ROUND(31 * SOFP!C22/319000, 0)&" days" -> 26 days
B19: Liquidity Ratios
B20: Current Ratio | C20: =ROUND(SUM(SOFP!C7:C10)/SUM(SOFP!C22:C24), 2)&" : 1" -> 3.46 : 1
B21: Quick (Acid Test) Ratio | C21: =ROUND(SUM(SOFP!C8:C10)/SUM(SOFP!C22:C24), 2)&" : 1" -> 3.22 : 1
B24: Solvency Ratios
B25: Gearing Ratio (debt/equity) | C25: =SOFP!D20/SOFP!D17 -> 0.2445563
B26: Interest Cover | C26: =ROUND(ABS(SOPL!C18/SUM(SOPL!C21:C21)), 1)&" times" -> 155.3 times

Sheet SOPL
B2: Statement of Profit or Loss for the month ended 31st January 2026
B3: PROFIT OR LOSS
B4: {=_xlfn._xlws.FILTER(chart_of_accounts[Account name], (chart_of_accounts[Code]>=4000) * ( chart_of_accounts[Code]<6000))} -> Revenue – Sale of Goods | C4: =_xlfn.XLOOKUP(B4, adjusted_trial_balance[Account Name], adjusted_trial_balance[Credit]) - _xlfn.XLOOKUP(B4, adjusted_trial_balance[Account Name], adjusted_trial_balance[Debit]) -> 530000
B5: Sales Returns | C5: =_xlfn.XLOOKUP(B5, adjusted_trial_balance[Account Name], adjusted_trial_balance[Credit]) - _xlfn.XLOOKUP(B5, adjusted_trial_balance[Account Name], adjusted_trial_balance[Debit]) -> -12000
B6: Cost of Sales | C6: =_xlfn.XLOOKUP(B6, adjusted_trial_balance[Account Name], adjusted_trial_balance[Credit]) - _xlfn.XLOOKUP(B6, adjusted_trial_balance[Account Name], adjusted_trial_balance[Debit]) -> -298000
B7: Inventory Write-down | C7: =_xlfn.XLOOKUP(B7, adjusted_trial_balance[Account Name], adjusted_trial_balance[Credit]) - _xlfn.XLOOKUP(B7, adjusted_trial_balance[Account Name], adjusted_trial_balance[Debit]) -> -1500
B8: Gross Profit | C8: =SUM(C4:C7) -> 218500
B9: {=_xlfn._xlws.FILTER(chart_of_accounts[Account name], (chart_of_accounts[Code]>=6000) * ( chart_of_accounts[Code]<7000))} -> Salaries & Wages | C9: =_xlfn.XLOOKUP(B9, adjusted_trial_balance[Account Name], adjusted_trial_balance[Credit]) - _xlfn.XLOOKUP(B9, adjusted_trial_balance[Account Name], adjusted_trial_balance[Debit]) -> -20500
B10: Rent Expense | C10: =_xlfn.XLOOKUP(B10, adjusted_trial_balance[Account Name], adjusted_trial_balance[Credit]) - _xlfn.XLOOKUP(B10, adjusted_trial_balance[Account Name], adjusted_trial_balance[Debit]) -> -8000
B11: Insurance Expense | C11: =_xlfn.XLOOKUP(B11, adjusted_trial_balance[Account Name], adjusted_trial_balance[Credit]) - _xlfn.XLOOKUP(B11, adjusted_trial_balance[Account Name], adjusted_trial_balance[Debit]) -> -1000
B12: Advertising Expense | C12: =_xlfn.XLOOKUP(B12, adjusted_trial_balance[Account Name], adjusted_trial_balance[Credit]) - _xlfn.XLOOKUP(B12, adjusted_trial_balance[Account Name], adjusted_trial_balance[Debit]) -> -5000
B13: Utilities Expense | C13: =_xlfn.XLOOKUP(B13, adjusted_trial_balance[Account Name], adjusted_trial_balance[Credit]) - _xlfn.XLOOKUP(B13, adjusted_trial_balance[Account Name], adjusted_trial_balance[Debit]) -> -5700
B14: Stationery Expense | C14: =_xlfn.XLOOKUP(B14, adjusted_trial_balance[Account Name], adjusted_trial_balance[Credit]) - _xlfn.XLOOKUP(B14, adjusted_trial_balance[Account Name], adjusted_trial_balance[Debit]) -> -1800
B15: Professional Fees | C15: =_xlfn.XLOOKUP(B15, adjusted_trial_balance[Account Name], adjusted_trial_balance[Credit]) - _xlfn.XLOOKUP(B15, adjusted_trial_balance[Account Name], adjusted_trial_balance[Debit]) -> -18000
B16: Depreciation Expense | C16: =_xlfn.XLOOKUP(B16, adjusted_trial_balance[Account Name], adjusted_trial_balance[Credit]) - _xlfn.XLOOKUP(B16, adjusted_trial_balance[Account Name], adjusted_trial_balance[Debit]) -> -1233.3333
B17: Bank Charges | C17: =_xlfn.XLOOKUP(B17, adjusted_trial_balance[Account Name], adjusted_trial_balance[Credit]) - _xlfn.XLOOKUP(B17, adjusted_trial_balance[Account Name], adjusted_trial_balance[Debit]) -> -2000
B18: Operating Profit | C18: =SUM(C8:C17) -> 155266.67
B19: Investment income | C19: 0
B20: Profit before financing and income taxes | C20: =SUM(C18:C19) -> 155266.67
B21: {=_xlfn._xlws.FILTER(chart_of_accounts[Account name], (chart_of_accounts[Code]>=7000) * ( chart_of_accounts[Code]<8000))} -> Loan Interest Expense | C21: =_xlfn.XLOOKUP(B21, adjusted_trial_balance[Account Name], adjusted_trial_balance[Credit]) - _xlfn.XLOOKUP(B21, adjusted_trial_balance[Account Name], adjusted_trial_balance[Debit]) -> -1000
B22: Profit before Income taxes | C22: =SUM(C20:C21) -> 154266.67
B23: {=_xlfn._xlws.FILTER(chart_of_accounts[Account name], (chart_of_accounts[Code]>=8000))} -> Income Tax Expense | C23: =_xlfn.XLOOKUP(B23, adjusted_trial_balance[Account Name], adjusted_trial_balance[Credit]) - _xlfn.XLOOKUP(B23, adjusted_trial_balance[Account Name], adjusted_trial_balance[Debit]) -> -45000
B24: Profit for the year ended | C24: =SUM(C22:C23) -> 109266.67

Sheet SOFP
B2: Statement of Financial Position as at 31st January 2026
B3: ASSETS
B4: Non Current Assets | C4: {=SUM(_xlfn._xlws.FILTER(adjusted_trial_balance[Debit], (chart_of_accounts[Code]>=1000) * ( chart_of_accounts[Code]<1200)))-SUM(_xlfn._xlws.FILTER(adjusted_trial_balance[Credit], (chart_of_accounts[Code]>=1000) * ( chart_of_accounts[Code]<1200)))} -> 52766.667
D5: =SUM(C4) -> 52766.667
B6: Current Assets
B7: {=_xlfn._xlws.FILTER(chart_of_accounts[Account name], (chart_of_accounts[Code] >= 1200) * (chart_of_accounts[Code] < 2000))} -> Inventory | C7: =_xlfn.XLOOKUP(B7, adjusted_trial_balance[Account Name], adjusted_trial_balance[Debit]) -> 74500
B8: Trade Receivables | C8: =_xlfn.XLOOKUP(B8, adjusted_trial_balance[Account Name], adjusted_trial_balance[Debit]) -> 223000
B9: Prepayments | C9: =_xlfn.XLOOKUP(B9, adjusted_trial_balance[Account Name], adjusted_trial_balance[Debit]) -> 11000
B10: Bank | C10: =_xlfn.XLOOKUP(B10, adjusted_trial_balance[Account Name], adjusted_trial_balance[Debit]) -> 746700
D11: =SUM(C7:C10) -> 1055200
B12: Total Assets | D12: =SUM(D5:D11) -> 1107966.7
B13: EQUITY AND LIABILITIES
B14: Equity
B15: {=_xlfn._xlws.FILTER(chart_of_accounts[Account name], (chart_of_accounts[Code] >= 2000) * (chart_of_accounts[Code] < 3000))} -> Ordinary Share Capital | C15: =_xlfn.XLOOKUP(B15, adjusted_trial_balance[Account Name], adjusted_trial_balance[Credit]) -> 500000
B16: Retained Earnings | C16: =_xlfn.XLOOKUP(B16, adjusted_trial_balance[Account Name], adjusted_trial_balance[Credit]) + SOPL!C24 -> 109266.67
D17: =SUM(C15:C16) -> 609266.67
B18: Noncurrent liabilities
B19: {=_xlfn._xlws.FILTER(chart_of_accounts[Account name], (chart_of_accounts[Code] >= 3000) * (chart_of_accounts[Code] < 3200))} -> Bank Loan | C19: =_xlfn.XLOOKUP(B19, adjusted_trial_balance[Account Name], adjusted_trial_balance[Credit]) -> 149000
D20: =SUM(C19) -> 149000
B21: Current Liabilities
B22: {=_xlfn._xlws.FILTER(chart_of_accounts[Account name], (chart_of_accounts[Code] >= 3200) * (chart_of_accounts[Code] < 4000))} -> Trade Payables | C22: =_xlfn.XLOOKUP(B22, adjusted_trial_balance[Account Name], adjusted_trial_balance[Credit]) -> 271000
B23: Accrued Expenses | C23: =_xlfn.XLOOKUP(B23, adjusted_trial_balance[Account Name], adjusted_trial_balance[Credit]) -> 3700
B24: Prepaid Income | C24: =_xlfn.XLOOKUP(B24, adjusted_trial_balance[Account Name], adjusted_trial_balance[Credit]) -> 30000
B25: Income Tax Payable | C25: =_xlfn.XLOOKUP(B25, adjusted_trial_balance[Account Name], adjusted_trial_balance[Credit]) -> 45000
D26: =SUM(C22:C25) -> 349700
B27: Total Equity and Liabilities | D27: =SUM(D17:D26) -> 1107966.7

Sheet SOCF
B2: Statement of Cash Flows for the month ended 31st January 2026
B3: CASH FLOW FROM OPERATING ACTIVITIES
B4: Operating Profit | C4: =SOPL!C18 -> 155266.67
B5: Depreciation Expense | C5: =-SOPL!C16 -> 1233.3333
B6: Operating profit before depreciation | C6: =SUM(C4:C5) -> 156500
B7: Increase in Inventory | C7: =-SOFP!C7 -> -74500
B8: Increase in Trade and other receivables | C8: =-((SOFP!C8 - 0) + (SOFP!C9 - 0)) -> -234000
B9: Increase in Trade and other payables | C9: =(SOFP!C22 - 0) + (SOFP!C23 - 0) + (SOFP!C24 - 0) -> 304700
B10: Cash from operating activities before income taxes | C10: =SUM(C6:C9) -> 152700
B11: Net cash from operating activities | D11: =SUM(C10:C10) -> 152700
B13: CASH FLOW FROM INVESTING ACTIVITIES
B14: Purchase of Furniture and Fixtures | C14: =-'adjusted_trial balance'!C4 -> -24000
B15: Purchase of Computer equipment | C15: =-'adjusted_trial balance'!C5 -> -30000
B16: Net cash used in investing activities | D16: =SUM(C14:C15) -> -54000
B18: CASH FLOW FROM FINANCING ACTIVITIES
B19: Proceeds from ordinary share issue | C19: =SOFP!C15 -> 500000
B20: Proceeds of bank loan (less arrangement fee) | C20: 148000
B21: Net cash from financing activities | D21: =SUM(C19:C20) -> 648000
B23: Net increase in cash and cash equivalents | D23: =SUM(D11:D22) -> 746700
B24: Cash and cash equivalents at beginning of period | D24: 0
B25: Cash and cash equivalents at end of period | D25: =SUM(D23:D24) -> 746700

Sheet chart_of_accounts
B2: Chart of Accounts
B3: Code | C3: Account name | D3: Account Type | E3: Account Subtype
B4: 1110 | C4: Furniture & Fixtures | D4: SOFP | E4: Non-current Asset – PPE
B5: 1120 | C5: Computer Equipment | D5: SOFP | E5: Non-current Asset – PPE
B6: 1190 | C6: Accumulated Depreciation – PPE | D6: SOFP | E6: Contra Asset
B7: 1310 | C7: Inventory | D7: SOFP | E7: Current Asset
B8: 1320 | C8: Trade Receivables | D8: SOFP | E8: Current Asset
B9: 1340 | C9: Prepayments | D9: SOFP | E9: Current Asset
B10: 1350 | C10: Bank | D10: SOFP | E10: Current Asset – Cash & Cash Equivalent
B11: 2100 | C11: Ordinary Share Capital | D11: SOFP | E11: Equity
B12: 2200 | C12: Retained Earnings | D12: SOFP | E12: Equity
B13: 3100 | C13: Bank Loan | D13: SOFP | E13: Non-current Liability
B14: 3310 | C14: Trade Payables | D14: SOFP | E14: Current Liability
B15: 3320 | C15: Accrued Expenses | D15: SOFP | E15: Current Liability
... B32: 8100 | C32: Income Tax Expense | D32: PnL | E32: Income Tax

Sheet general_journal
B2: General Journal
B3: Date | C3: JRN No. | D3: Code | E3: Account Name | F3: Description | G3: Debit | H3: Credit
B4: 46023 | C4: J001 | D4: =_xlfn.XLOOKUP(general_journal!$E4, chart_of_accounts[Account name], chart_of_accounts[Code]) -> 1350 | E4: Bank | F4: Issued ordinary shares (at $1 per share) | G4: 500000
B5: 46023 | C5: J001 | D5: =_xlfn.XLOOKUP(general_journal!$E5, chart_of_accounts[Account name], chart_of_accounts[Code]) -> 2100 | E5: Ordinary Share Capital | F5: Issued ordinary shares (at $1 per share) | H5: 500000
B6: 46024 | C6: J002 | D6: =_xlfn.XLOOKUP(general_journal!$E6, chart_of_accounts[Account name], chart_of_accounts[Code]) -> 6700 | E6: Professional Fees | F6: Legal and professional fees for company establishment | G6: 12000
B7: 46024 | C7: J002 | D7: =_xlfn.XLOOKUP(general_journal!$E7, chart_of_accounts[Account name], chart_of_accounts[Code]) -> 1350 | E7: Bank | F7: Legal and professional fees for company establishment | H7: 12000
B8: 46025 | C8: J003 | D8: =_xlfn.XLOOKUP(general_journal!$E8, chart_of_accounts[Account name], chart_of_accounts[Code]) -> 1110 | E8: Furniture & Fixtures | F8: Purchase of office furniture (5 years) | G8: 24000
B9: 46025 | C9: J003 | D9: =_xlfn.XLOOKUP(general_journal!$E9, chart_of_accounts[Account name], chart_of_accounts[Code]) -> 1350 | E9: Bank | F9: Purchase of office furniture (5 years) | H9: 24000
B10: 46026 | C10: J004 | D10: =_xlfn.XLOOKUP(general_journal!$E10, chart_of_accounts[Account name], chart_of_accounts[Code]) -> 1120 | E10: Computer Equipment | F10: Purchased computer equipment (3 years) | G10: 30000
B11: 46026 | C11: J004 | D11: =_xlfn.XLOOKUP(general_journal!$E11, chart_of_accounts[Account name], chart_of_accounts[Code]) -> 1350 | E11: Bank | F11: Purchased computer equipment (3 years) | H11: 30000
B12: 46027 | C12: J005 | D12: =_xlfn.XLOOKUP(general_journal!$E12, chart_of_accounts[Account name], chart_of_accounts[Code]) -> 6200 | E12: Rent Expense | F12: Office rent for January | G12: 8000
B13: 46027 | C13: J005 | D13: =_xlfn.XLOOKUP(general_journal!$E13, chart_of_accounts[Account name], chart_of_accounts[Code]) -> 1350 | E13: Bank | F13: Office rent for January | H13: 8000
B14: 46028 | C14: J006 | D14: =_xlfn.XLOOKUP(general_journal!$E14, chart_of_accounts[Account name], chart_of_accounts[Code]) -> 1340 | E14: Prepayments | F14: 12-month insurance policy purchase | G14: 12000
B15: 46028 | C15: J006 | D15: =_xlfn.XLOOKUP(general_journal!$E15, chart_of_accounts[Account name], chart_of_accounts[Code]) -> 1350 | E15: Bank | F15: 12-month insurance policy purchase | H15: 12000
B16: 46029 | C16: J007 | D16: =_xlfn.XLOOKUP(general_journal!$E16, chart_of_accounts[Account name], chart_of_accounts[Code]) -> 6600 | E16: Stationery Expense | F16: Stationary purchase | G16: 1800
B17: 46029 | C17: J007 | D17: =_xlfn.XLOOKUP(general_journal!$E17, chart_of_accounts[Account name], chart_of_accounts[Code]) -> 1350 | E17: Bank | F17: Stationary purchase | H17: 1800
B18: 46030 | C18: J008 | D18: =_xlfn.XLOOKUP(general_journal!$E18, chart_of_accounts[Account name], chart_of_accounts[Code]) -> 1310 | E18: Inventory | F18: Inventory purchase from Alpha Supplies on credit | G18: 75000
B19: 46030 | C19: J008 | D19: =_xlfn.XLOOKUP(general_journal!$E19, chart_of_accounts[Account name], chart_of_accounts[Code]) -> 3310 | E19: Trade Payables | F19: Inventory purchase from Alpha Supplies on credit | H19: 75000
B20: 46031 | C20: J009 | D20: =_xlfn.XLOOKUP(general_journal!$E20, chart_of_accounts[Account name], chart_of_accounts[Code]) -> 1310 | E20: Inventory | F20: Frieght and handling costs | G20: 3000
B21: 46031 | C21: J009 | D21: =_xlfn.XLOOKUP(general_journal!$E21, chart_of_accounts[Account name], chart_of_accounts[Code]) -> 1350 | E21: Bank | F21: Frieght and handling costs | H21: 3000
B22: 46032 | C22: J010 | D22: =_xlfn.XLOOKUP(general_journal!$E22, chart_of_accounts[Account name], chart_of_accounts[Code]) -> 1310 | E22: Inventory | F22: Inventory purchase from Beta Distribution | G22: 60000
B23: 46032 | C23: J010 | D23: =_xlfn.XLOOKUP(general_journal!$E23, chart_of_accounts[Account name], chart_of_accounts[Code]) -> 1350 | E23: Bank | F23: Inventory purchase from Beta Distribution | H23: 60000
B24: 46033 | C24: J011 | D24: =_xlfn.XLOOKUP(general_journal!$E24, chart_of_accounts[Account name], chart_of_accounts[Code]) -> 1320 | E24: Trade Receivables | F24: Sold goods to Customer A on credit | G24: 110000
B25: 46033 | C25: J011 | D25: =_xlfn.XLOOKUP(general_journal!$E25, chart_of_accounts[Account name], chart_of_accounts[Code]) -> 4100 | E25: Revenue – Sale of Goods | F25: Sold goods to Customer A on credit | H25: 110000
B26: 46033 | C26: J012 | D26: =_xlfn.XLOOKUP(general_journal!$E26, chart_of_accounts[Account name], chart_of_accounts[Code]) -> 5100 | E26: Cost of Sales | F26: Cost of sales regarding sales made to Customer A | G26: 63000
B27: 46033 | C27: J012 | D27: =_xlfn.XLOOKUP(general_journal!$E27, chart_of_accounts[Account name], chart_of_accounts[Code]) -> 1310 | E27: Inventory | F27: Cost of sales regarding sales made to Customer A | H27: 63000
B28: 46034 | C28: J013 | D28: =_xlfn.XLOOKUP(general_journal!$E28, chart_of_accounts[Account name], chart_of_accounts[Code]) -> 3310 | E28: Trade Payables | F28: Inventory return to Alpha supplies | G28: 8000
B29: 46034 | C29: J013 | D29: =_xlfn.XLOOKUP(general_journal!$E29, chart_of_accounts[Account name], chart_of_accounts[Code]) -> 1310 | E29: Inventory | F29: Inventory return to Alpha supplies | H29: 8000
B30: 46036 | C30: J014 | D30: =_xlfn.XLOOKUP(general_journal!$E30, chart_of_accounts[Account name], chart_of_accounts[Code]) -> 1350 | E30: Bank | F30: Made cash sale | G30: 55000
B31: 46036 | C31: J014 | D31: =_xlfn.XLOOKUP(general_journal!$E31, chart_of_accounts[Account name], chart_of_accounts[Code]) -> 4100 | E31: Revenue – Sale of Goods | F31: Made cash sale | H31: 55000
B32: 46036 | C32: J015 | D32: =_xlfn.XLOOKUP(general_journal!$E32, chart_of_accounts[Account name], chart_of_accounts[Code]) -> 5100 | E32: Cost of Sales | F32: Cost of sales regarding the cash sales | G32: 31000
B33: 46036 | C33: J015 | D33: =_xlfn.XLOOKUP(general_journal!$E33, chart_of_accounts[Account name], chart_of_accounts[Code]) -> 1310 | E33: Inventory | F33: Cost of sales regarding the cash sales | H33: 31000
B34: 46037 | C34: J016 | D34: =_xlfn.XLOOKUP(general_journal!$E34, chart_of_accounts[Account name], chart_of_accounts[Code]) -> 1310 | E34: Inventory | F34: Inventory purchase from Gamma Tech on credit | G34: 244000
B35: 46037 | C35: J016 | D35: =_xlfn.XLOOKUP(general_journal!$E35, chart_of_accounts[Account name], chart_of_accounts[Code]) -> 3310 | E35: Trade Payables | F35: Inventory purchase from Gamma Tech on credit | H35: 244000
B36: 46039 | C36: J017 | D36: =_xlfn.XLOOKUP(general_journal!$E36, chart_of_accounts[Account name], chart_of_accounts[Code]) -> 1320 | E36: Trade Receivables | F36: Sold goods to Customer B on credit | G36: 135000
B37: 46039 | C37: J017 | D37: =_xlfn.XLOOKUP(general_journal!$E37, chart_of_accounts[Account name], chart_of_accounts[Code]) -> 4100 | E37: Revenue – Sale of Goods | F37: Sold goods to Customer B on credit | H37: 135000
B38: 46039 | C38: J018 | D38: =_xlfn.XLOOKUP(general_journal!$E38, chart_of_accounts[Account name], chart_of_accounts[Code]) -> 5100 | E38: Cost of Sales | F38: Cost of sales regarding sales made to Customer B | G38: 78000
B39: 46039 | C39: J018 | D39: =_xlfn.XLOOKUP(general_journal!$E39, chart_of_accounts[Account name], chart_of_accounts[Code]) -> 1310 | E39: Inventory | F39: Cost of sales regarding sales made to Customer B | H39: 78000
B40: 46040 | C40: J019 | D40: =_xlfn.XLOOKUP(general_journal!$E40, chart_of_accounts[Account name], chart_of_accounts[Code]) -> 3310 | E40: Trade Payables | F40: Paid part of the outstanding amount to Alpha Supplies | G40: 40000
B41: 46040 | C41: J019 | D41: =_xlfn.XLOOKUP(general_journal!$E41, chart_of_accounts[Account name], chart_of_accounts[Code]) -> 1350 | E41: Bank | F41: Paid part of the outstanding amount to Alpha Supplies | H41: 40000
...

Sheet general_ledger
B2: (Change Account name using the dropdown to obtain individual ledger accounts)
B3: General Ledger
B4: Bank
B5: Date | C5: JRN No. | D5: Description | E5: Debit | F5: Credit | G5: Balance
D6: Opening Balance | G6: 0
B8: {=_xlfn._xlws.FILTER(_xlfn.CHOOSECOLS(general_journal[], _xlfn.XMATCH(B5:F5, general_journal[#Headers],0,1)), general_journal[Account Name] = B4)} -> 46023 | C8: J001 | D8: Issued ordinary shares (at $1 per share) | E8: 500000 | F8: 0 | G8: =IF(OR(E8<>0, F8<>0), G6+E8-F8, 0) -> 500000
B9: 46024 | C9: J002 | D9: Legal and professional fees for company establishment | E9: 0 | F9: 12000 | G9: =IF(OR(E9<>0, F9<>0), G8+E9-F9, 0) -> 488000
B10: 46025 | C10: J003 | D10: Purchase of office furniture (5 years) | E10: 0 | F10: 24000 | G10: =IF(OR(E10<>0, F10<>0), G9+E10-F10, 0) -> 464000
B11: 46026 | C11: J004 | D11: Purchased computer equipment (3 years) | E11: 0 | F11: 30000 | G11: =IF(OR(E11<>0, F11<>0), G10+E11-F11, 0) -> 434000
B12: 46027 | C12: J005 | D12: Office rent for January | E12: 0 | F12: 8000 | G12: =IF(OR(E12<>0, F12<>0), G11+E12-F12, 0) -> 426000
B13: 46028 | C13: J006 | D13: 12-month insurance policy purchase | E13: 0 | F13: 12000 | G13: =IF(OR(E13<>0, F13<>0), G12+E13-F13, 0) -> 414000
B14: 46029 | C14: J007 | D14: Stationary purchase | E14: 0 | F14: 1800 | G14: =IF(OR(E14<>0, F14<>0), G13+E14-F14, 0) -> 412200
B15: 46031 | C15: J009 | D15: Frieght and handling costs | E15: 0 | F15: 3000 | G15: =IF(OR(E15<>0, F15<>0), G14+E15-F15, 0) -> 409200
B16: 46032 | C16: J010 | D16: Inventory purchase from Beta Distribution | E16: 0 | F16: 60000 | G16: =IF(OR(E16<>0, F16<>0), G15+E16-F16, 0) -> 349200
B17: 46036 | C17: J014 | D17: Made cash sale | E17: 55000 | F17: 0 | G17: =IF(OR(E17<>0, F17<>0), G16+E17-F17, 0) -> 404200
B18: 46040 | C18: J019 | D18: Paid part of the outstanding amount to Alpha Supplies | E18: 0 | F18: 40000 | G18: =IF(OR(E18<>0, F18<>0), G17+E18-F18, 0) -> 364200
B19: 46042 | C19: J020 | D19: Part of balance paid by Customer A | E19: 70000 | F19: 0 | G19: =IF(OR(E19<>0, F19<>0), G18+E19-F19, 0) -> 434200
B20: 46044 | C20: J023 | D20: Three-year bank loan | E20: 150000 | F20: 0 | G20: =IF(OR(E20<>0, F20<>0), G19+E20-F20, 0) -> 584200
... B29: 46053 | C29: J035 | D29: Fees for accounting and reporting work | E29: 0 | F29: 6000 | G29: =IF(OR(E29<>0, F29<>0), G28+E29-F29, 0) -> 746700
D32: Closing Balance | G32: {=SUM(E8:E29, -F8:F29)} -> 746700

Sheet adjusted_trial balance
B2: Adjusted Trial Balance
B3: Account Name | C3: Debit | D3: Credit
B4: =chart_of_accounts[[#This Row],[Account name]] -> Furniture & Fixtures | C4: {=IFERROR( IF( SUM(IFERROR(_xlfn._xlws.FILTER(general_journal[Debit], general_journal[Account Name] = B4), 0)) > SUM(IFERROR(_xlfn._xlws.FILTER(general_journal[Credit], general_journal[Account Name] = B4), 0)), SUM(IFERROR(_xlfn._xlws.FILTER(general_journal[Debit], general_journal[Account Name] = B4), 0)) - SUM(IFERROR(_xlfn._xlws.FILTER(general_journal[Credit], general_journal[Account Name] = B4), 0)), 0 ), 0)} -> 24000 | D4: {=IFERROR( IF( SUM(IFERROR(_xlfn._xlws.FILTER(general_journal[Debit], general_journal[Account Name] = B4), 0)) < SUM(IFERROR(_xlfn._xlws.FILTER(general_journal[Credit], general_journal[Account Name] = B4), 0)), SUM(IFERROR(_xlfn._xlws.FILTER(general_journal[Credit], general_journal[Account Name] = B4), 0)) - SUM(IFERROR(_xlfn._xlws.FILTER(general_journal[Debit], general_journal[Account Name] = B4), 0)), 0 ), 0)} -> 0
B5: =chart_of_accounts[[#This Row],[Account name]] -> Computer Equipment | C5: {=IFERROR( IF( SUM(IFERROR(_xlfn._xlws.FILTER(general_journal[Debit], general_journal[Account Name] = B5), 0)) > SUM(IFERROR(_xlfn._xlws.FILTER(general_journal[Credit], general_journal[Account Name] = B5), 0)), SUM(IFERROR(_xlfn._xlws.FILTER(general_journal[Debit], general_journal[Account Name] = B5), 0)) - SUM(IFERROR(_xlfn._xlws.FILTER(general_journal[Credit], general_journal[Account Name] = B5), 0)), 0 ), 0)} -> 30000 | D5: {=IFERROR( IF( SUM(IFERROR(_xlfn._xlws.FILTER(general_journal[Debit], general_journal[Account Name] = B5), 0)) < SUM(IFERROR(_xlfn._xlws.FILTER(general_journal[Credit], general_journal[Account Name] = B5), 0)), SUM(IFERROR(_xlfn._xlws.FILTER(general_journal[Credit], general_journal[Account Name] = B5), 0)) - SUM(IFERROR(_xlfn._xlws.FILTER(general_journal[Debit], general_journal[Account Name] = B5), 0)), 0 ), 0)} -> 0
B6: =chart_of_accounts[[#This Row],[Account name]] -> Accumulated Depreciation – PPE | C6: {=IFERROR( IF( SUM(IFERROR(_xlfn._xlws.FILTER(general_journal[Debit], general_journal[Account Name] = B6), 0)) > SUM(IFERROR(_xlfn._xlws.FILTER(general_journal[Credit], general_journal[Account Name] = B6), 0)), SUM(IFERROR(_xlfn._xlws.FILTER(general_journal[Debit], general_journal[Account Name] = B6), 0)) - SUM(IFERROR(_xlfn._xlws.FILTER(general_journal[Credit], general_journal[Account Name] = B6), 0)), 0 ), 0)} -> 0 | D6: {=IFERROR( IF( SUM(IFERROR(_xlfn._xlws.FILTER(general_journal[Debit], general_journal[Account Name] = B6), 0)) < SUM(IFERROR(_xlfn._xlws.FILTER(general_journal[Credit], general_journal[Account Name] = B6), 0)), SUM(IFERROR(_xlfn._xlws.FILTER(general_journal[Credit], general_journal[Account Name] = B6), 0)) - SUM(IFERROR(_xlfn._xlws.FILTER(general_journal[Debit], general_journal[Account Name] = B6), 0)), 0 ), 0)} -> 1233.3333
B7: =chart_of_accounts[[#This Row],[Account name]] -> Inventory | C7: {=IFERROR( IF( SUM(IFERROR(_xlfn._xlws.FILTER(general_journal[Debit], general_journal[Account Name] = B7), 0)) > SUM(IFERROR(_xlfn._xlws.FILTER(general_journal[Credit], general_journal[Account Name] = B7), 0)), SUM(IFERROR(_xlfn._xlws.FILTER(general_journal[Debit], general_journal[Account Name] = B7), 0)) - SUM(IFERROR(_xlfn._xlws.FILTER(general_journal[Credit], general_journal[Account Name] = B7), 0)), 0 ), 0)} -> 74500 | D7: {=IFERROR( IF( SUM(IFERROR(_xlfn._xlws.FILTER(general_journal[Debit], general_journal[Account Name] = B7), 0)) < SUM(IFERROR(_xlfn._xlws.FILTER(general_journal[Credit], general_journal[Account Name] = B7), 0)), SUM(IFERROR(_xlfn._xlws.FILTER(general_journal[Credit], general_journal[Account Name] = B7), 0)) - SUM(IFERROR(_xlfn._xlws.FILTER(general_journal[Debit], general_journal[Account Name] = B7), 0)), 0 ), 0)} -> 0
B8: =chart_of_accounts[[#This Row],[Account name]] -> Trade Receivables | C8: {=IFERROR( IF( SUM(IFERROR(_xlfn._xlws.FILTER(general_journal[Debit], general_journal[Account Name] = B8), 0)) > SUM(IFERROR(_xlfn._xlws.FILTER(general_journal[Credit], general_journal[Account Name] = B8), 0)), SUM(IFERROR(_xlfn._xlws.FILTER(general_journal[Debit], general_journal[Account Name] = B8), 0)) - SUM(IFERROR(_xlfn._xlws.FILTER(general_journal[Credit], general_journal[Account Name] = B8), 0)), 0 ), 0)} -> 223000 | D8: {=IFERROR( IF( SUM(IFERROR(_xlfn._xlws.FILTER(general_journal[Debit], general_journal[Account Name] = B8), 0)) < SUM(IFERROR(_xlfn._xlws.FILTER(general_journal[Credit], general_journal[Account Name] = B8), 0)), SUM(IFERROR(_xlfn._xlws.FILTER(general_journal[Credit], general_journal[Account Name] = B8), 0)) - SUM(IFERROR(_xlfn._xlws.FILTER(general_journal[Debit], general_journal[Account Name] = B8), 0)), 0 ), 0)} -> 0
B9: =chart_of_accounts[[#This Row],[Account name]] -> Prepayments | C9: {=IFERROR( IF( SUM(IFERROR(_xlfn._xlws.FILTER(general_journal[Debit], general_journal[Account Name] = B9), 0)) > SUM(IFERROR(_xlfn._xlws.FILTER(general_journal[Credit], general_journal[Account Name] = B9), 0)), SUM(IFERROR(_xlfn._xlws.FILTER(general_journal[Debit], general_journal[Account Name] = B9), 0)) - SUM(IFERROR(_xlfn._xlws.FILTER(general_journal[Credit], general_journal[Account Name] = B9), 0)), 0 ), 0)} -> 11000 | D9: {=IFERROR( IF( SUM(IFERROR(_xlfn._xlws.FILTER(general_journal[Debit], general_journal[Account Name] = B9), 0)) < SUM(IFERROR(_xlfn._xlws.FILTER(general_journal[Credit], general_journal[Account Name] = B9), 0)), SUM(IFERROR(_xlfn._xlws.FILTER(general_journal[Credit], general_journal[Account Name] = B9), 0)) - SUM(IFERROR(_xlfn._xlws.FILTER(general_journal[Debit], general_journal[Account Name] = B9), 0)), 0 ), 0)} -> 0
B10: =chart_of_accounts[[#This Row],[Account name]] -> Bank | C10: {=IFERROR( IF( SUM(IFERROR(_xlfn._xlws.FILTER(general_journal[Debit], general_journal[Account Name] = B10), 0)) > SUM(IFERROR(_xlfn._xlws.FILTER(general_journal[Credit], general_journal[Account Name] = B10), 0)), SUM(IFERROR(_xlfn._xlws.FILTER(general_journal[Debit], general_journal[Account Name] = B10), 0)) - SUM(IFERROR(_xlfn._xlws.FILTER(general_journal[Credit], general_journal[Account Name] = B10), 0)), 0 ), 0)} -> 746700 | D10: {=IFERROR( IF( SUM(IFERROR(_xlfn._xlws.FILTER(general_journal[Debit], general_journal[Account Name] = B10), 0)) < SUM(IFERROR(_xlfn._xlws.FILTER(general_journal[Credit], general_journal[Account Name] = B10), 0)), SUM(IFERROR(_xlfn._xlws.FILTER(general_journal[Credit], general_journal[Account Name] = B10), 0)) - SUM(IFERROR(_xlfn._xlws.FILTER(general_journal[Debit], general_journal[Account Name] = B10), 0)), 0 ), 0)} -> 0
B11: =chart_of_accounts[[#This Row],[Account name]] -> Ordinary Share Capital | C11: {=IFERROR( IF( SUM(IFERROR(_xlfn._xlws.FILTER(general_journal[Debit], general_journal[Account Name] = B11), 0)) > SUM(IFERROR(_xlfn._xlws.FILTER(general_journal[Credit], general_journal[Account Name] = B11), 0)), SUM(IFERROR(_xlfn._xlws.FILTER(general_journal[Debit], general_journal[Account Name] = B11), 0)) - SUM(IFERROR(_xlfn._xlws.FILTER(general_journal[Credit], general_journal[Account Name] = B11), 0)), 0 ), 0)} -> 0 | D11: {=IFERROR( IF( SUM(IFERROR(_xlfn._xlws.FILTER(general_journal[Debit], general_journal[Account Name] = B11), 0)) < SUM(IFERROR(_xlfn._xlws.FILTER(general_journal[Credit], general_journal[Account Name] = B11), 0)), SUM(IFERROR(_xlfn._xlws.FILTER(general_journal[Credit], general_journal[Account Name] = B11), 0)) - SUM(IFERROR(_xlfn._xlws.FILTER(general_journal[Debit], general_journal[Account Name] = B11), 0)), 0 ), 0)} -> 500000
B12: =chart_of_accounts[[#This Row],[Account name]] -> Retained Earnings | C12: {=IFERROR( IF( SUM(IFERROR(_xlfn._xlws.FILTER(general_journal[Debit], general_journal[Account Name] = B12), 0)) > SUM(IFERROR(_xlfn._xlws.FILTER(general_journal[Credit], general_journal[Account Name] = B12), 0)), SUM(IFERROR(_xlfn._xlws.FILTER(general_journal[Debit], general_journal[Account Name] = B12), 0)) - SUM(IFERROR(_xlfn._xlws.FILTER(general_journal[Credit], general_journal[Account Name] = B12), 0)), 0 ), 0)} -> 0 | D12: {=IFERROR( IF( SUM(IFERROR(_xlfn._xlws.FILTER(general_journal[Debit], general_journal[Account Name] = B12), 0)) < SUM(IFERROR(_xlfn._xlws.FILTER(general_journal[Credit], general_journal[Account Name] = B12), 0)), SUM(IFERROR(_xlfn._xlws.FILTER(general_journal[Credit], general_journal[Account Name] = B12), 0)) - SUM(IFERROR(_xlfn._xlws.FILTER(general_journal[Debit], general_journal[Account Name] = B12), 0)), 0 ), 0)} -> 0
B13: =chart_of_accounts[[#This Row],[Account name]] -> Bank Loan | C13: {=IFERROR( IF( SUM(IFERROR(_xlfn._xlws.FILTER(general_journal[Debit], general_journal[Account Name] = B13), 0)) > SUM(IFERROR(_xlfn._xlws.FILTER(general_journal[Credit], general_journal[Account Name] = B13), 0)), SUM(IFERROR(_xlfn._xlws.FILTER(general_journal[Debit], general_journal[Account Name] = B13), 0)) - SUM(IFERROR(_xlfn._xlws.FILTER(general_journal[Credit], general_journal[Account Name] = B13), 0)), 0 ), 0)} -> 0 | D13: {=IFERROR( IF( SUM(IFERROR(_xlfn._xlws.FILTER(general_journal[Debit], general_journal[Account Name] = B13), 0)) < SUM(IFERROR(_xlfn._xlws.FILTER(general_journal[Credit], general_journal[Account Name] = B13), 0)), SUM(IFERROR(_xlfn._xlws.FILTER(general_journal[Credit], general_journal[Account Name] = B13), 0)) - SUM(IFERROR(_xlfn._xlws.FILTER(general_journal[Debit], general_journal[Account Name] = B13), 0)), 0 ), 0)} -> 149000
B14: =chart_of_accounts[[#This Row],[Account name]] -> Trade Payables | C14: {=IFERROR( IF( SUM(IFERROR(_xlfn._xlws.FILTER(general_journal[Debit], general_journal[Account Name] = B14), 0)) > SUM(IFERROR(_xlfn._xlws.FILTER(general_journal[Credit], general_journal[Account Name] = B14), 0)), SUM(IFERROR(_xlfn._xlws.FILTER(general_journal[Debit], general_journal[Account Name] = B14), 0)) - SUM(IFERROR(_xlfn._xlws.FILTER(general_journal[Credit], general_journal[Account Name] = B14), 0)), 0 ), 0)} -> 0 | D14: {=IFERROR( IF( SUM(IFERROR(_xlfn._xlws.FILTER(general_journal[Debit], general_journal[Account Name] = B14), 0)) < SUM(IFERROR(_xlfn._xlws.FILTER(general_journal[Credit], general_journal[Account Name] = B14), 0)), SUM(IFERROR(_xlfn._xlws.FILTER(general_journal[Credit], general_journal[Account Name] = B14), 0)) - SUM(IFERROR(_xlfn._xlws.FILTER(general_journal[Debit], general_journal[Account Name] = B14), 0)), 0 ), 0)} -> 271000
B15: =chart_of_accounts[[#This Row],[Account name]] -> Accrued Expenses | C15: {=IFERROR( IF( SUM(IFERROR(_xlfn._xlws.FILTER(general_journal[Debit], general_journal[Account Name] = B15), 0)) > SUM(IFERROR(_xlfn._xlws.FILTER(general_journal[Credit], general_journal[Account Name] = B15), 0)), SUM(IFERROR(_xlfn._xlws.FILTER(general_journal[Debit], general_journal[Account Name] = B15), 0)) - SUM(IFERROR(_xlfn._xlws.FILTER(general_journal[Credit], general_journal[Account Name] = B15), 0)), 0 ), 0)} -> 0 | D15: {=IFERROR( IF( SUM(IFERROR(_xlfn._xlws.FILTER(general_journal[Debit], general_journal[Account Name] = B15), 0)) < SUM(IFERROR(_xlfn._xlws.FILTER(general_journal[Credit], general_journal[Account Name] = B15), 0)), SUM(IFERROR(_xlfn._xlws.FILTER(general_journal[Credit], general_journal[Account Name] = B15), 0)) - SUM(IFERROR(_xlfn._xlws.FILTER(general_journal[Debit], general_journal[Account Name] = B15), 0)), 0 ), 0)} -> 3700
... B30: =chart_of_accounts[[#This Row],[Account name]] -> Bank Charges | C30: {=IFERROR( IF( SUM(IFERROR(_xlfn._xlws.FILTER(general_journal[Debit], general_journal[Account Name] = B30), 0)) > SUM(IFERROR(_xlfn._xlws.FILTER(general_journal[Credit], general_journal[Account Name] = B30), 0)), SUM(IFERROR(_xlfn._xlws.FILTER(general_journal[Debit], general_journal[Account Name] = B30), 0)) - SUM(IFERROR(_xlfn._xlws.FILTER(general_journal[Credit], general_journal[Account Name] = B30), 0)), 0 ), 0)} -> 2000 | D30: {=IFERROR( IF( SUM(IFERROR(_xlfn._xlws.FILTER(general_journal[Debit], general_journal[Account Name] = B30), 0)) < SUM(IFERROR(_xlfn._xlws.FILTER(general_journal[Credit], general_journal[Account Name] = B30), 0)), SUM(IFERROR(_xlfn._xlws.FILTER(general_journal[Credit], general_journal[Account Name] = B30), 0)) - SUM(IFERROR(_xlfn._xlws.FILTER(general_journal[Debit], general_journal[Account Name] = B30), 0)), 0 ), 0)} -> 0
B31: =chart_of_accounts[[#This Row],[Account name]] -> Loan Interest Expense | C31: {=IFERROR( IF( SUM(IFERROR(_xlfn._xlws.FILTER(general_journal[Debit], general_journal[Account Name] = B31), 0)) > SUM(IFERROR(_xlfn._xlws.FILTER(general_journal[Credit], general_journal[Account Name] = B31), 0)), SUM(IFERROR(_xlfn._xlws.FILTER(general_journal[Debit], general_journal[Account Name] = B31), 0)) - SUM(IFERROR(_xlfn._xlws.FILTER(general_journal[Credit], general_journal[Account Name] = B31), 0)), 0 ), 0)} -> 1000
B32: =chart_of_accounts[[#This Row],[Account name]] -> Income Tax Expense | C32: {=IFERROR( IF( SUM(IFERROR(_xlfn._xlws.FILTER(general_journal[Debit], general_journal[Account Name] = B32), 0)) > SUM(IFERROR(_xlfn._xlws.FILTER(general_journal[Credit], general_journal[Account Name] = B32), 0)), SUM(IFERROR(_xlfn._xlws.FILTER(general_journal[Debit], general_journal[Account Name] = B32), 0)) - SUM(IFERROR(_xlfn._xlws.FILTER(general_journal[Credit], general_journal[Account Name] = B32), 0)), 0 ), 0)} -> 45000
B33: Total | C33: =SUBTOTAL(109,adjusted_trial_balance[Debit]) -> 1529933.3 | D33: =SUBTOTAL(109,adjusted_trial_balance[Credit]) -> 1529933.3

Sheet closing_entries
B2: Closing Entries
B3: Date | C3: JRN No. | D3: Code | E3: Account Name | F3: Description | G3: Debit | H3: Credit
B4: 46053 | C4: J043 | D4: =_xlfn.XLOOKUP(E4, chart_of_accounts[Account name], chart_of_accounts[Code]) -> 4100 | E4: Revenue – Sale of Goods | F4: Closing Entry | G4: 530000
B5: 46053 | C5: J043 | D5: =_xlfn.XLOOKUP(E5, chart_of_accounts[Account name], chart_of_accounts[Code]) -> 4300 | E5: Sales Returns | F5: Closing Entry | H5: =_xlfn.XLOOKUP(E5, adjusted_trial_balance[Account Name], adjusted_trial_balance[Debit]) -> 12000
B6: 46053 | C6: J043 | D6: =_xlfn.XLOOKUP(E6, chart_of_accounts[Account name], chart_of_accounts[Code]) -> 5100 | E6: Cost of Sales | F6: Closing Entry | H6: =_xlfn.XLOOKUP(E6, adjusted_trial_balance[Account Name], adjusted_trial_balance[Debit]) -> 298000
B7: 46053 | C7: J043 | D7: =_xlfn.XLOOKUP(E7, chart_of_accounts[Account name], chart_of_accounts[Code]) -> 5200 | E7: Inventory Write-down | F7: Closing Entry | H7: =_xlfn.XLOOKUP(E7, adjusted_trial_balance[Account Name], adjusted_trial_balance[Debit]) -> 1500
B8: 46053 | C8: J043 | D8: =_xlfn.XLOOKUP(E8, chart_of_accounts[Account name], chart_of_accounts[Code]) -> 6100 | E8: Salaries & Wages | F8: Closing Entry | H8: =_xlfn.XLOOKUP(E8, adjusted_trial_balance[Account Name], adjusted_trial_balance[Debit]) -> 20500
B9: 46053 | C9: J043 | D9: =_xlfn.XLOOKUP(E9, chart_of_accounts[Account name], chart_of_accounts[Code]) -> 6200 | E9: Rent Expense | F9: Closing Entry | H9: =_xlfn.XLOOKUP(E9, adjusted_trial_balance[Account Name], adjusted_trial_balance[Debit]) -> 8000
B10: 46053 | C10: J043 | D10: =_xlfn.XLOOKUP(E10, chart_of_accounts[Account name], chart_of_accounts[Code]) -> 6300 | E10: Insurance Expense | F10: Closing Entry | H10: =_xlfn.XLOOKUP(E10, adjusted_trial_balance[Account Name], adjusted_trial_balance[Debit]) -> 1000
B11: 46053 | C11: J043 | D11: =_xlfn.XLOOKUP(E11, chart_of_accounts[Account name], chart_of_accounts[Code]) -> 6400 | E11: Advertising Expense | F11: Closing Entry | H11: =_xlfn.XLOOKUP(E11, adjusted_trial_balance[Account Name], adjusted_trial_balance[Debit]) -> 5000
B12: 46053 | C12: J043 | D12: =_xlfn.XLOOKUP(E12, chart_of_accounts[Account name], chart_of_accounts[Code]) -> 6500 | E12: Utilities Expense | F12: Closing Entry | H12: =_xlfn.XLOOKUP(E12, adjusted_trial_balance[Account Name], adjusted_trial_balance[Debit]) -> 5700
B13: 46053 | C13: J043 | D13: =_xlfn.XLOOKUP(E13, chart_of_accounts[Account name], chart_of_accounts[Code]) -> 6600 | E13: Stationery Expense | F13: Closing Entry | H13: =_xlfn.XLOOKUP(E13, adjusted_trial_balance[Account Name], adjusted_trial_balance[Debit]) -> 1800
B14: 46053 | C14: J043 | D14: =_xlfn.XLOOKUP(E14, chart_of_accounts[Account name], chart_of_accounts[Code]) -> 6700 | E14: Professional Fees | F14: Closing Entry | H14: =_xlfn.XLOOKUP(E14, adjusted_trial_balance[Account Name], adjusted_trial_balance[Debit]) -> 18000
B15: 46053 | C15: J043 | D15: =_xlfn.XLOOKUP(E15, chart_of_accounts[Account name], chart_of_accounts[Code]) -> 6800 | E15: Depreciation Expense | F15: Closing Entry | H15: =_xlfn.XLOOKUP(E15, adjusted_trial_balance[Account Name], adjusted_trial_balance[Debit]) -> 1233.3333
B16: 46053 | C16: J043 | D16: =_xlfn.XLOOKUP(E16, chart_of_accounts[Account name], chart_of_accounts[Code]) -> 7100 | E16: Loan Interest Expense | F16: Closing Entry | H16: =_xlfn.XLOOKUP(E16, adjusted_trial_balance[Account Name], adjusted_trial_balance[Debit]) -> 1000
... B18: 46053 | C18: J043 | D18: =_xlfn.XLOOKUP(E18, chart_of_accounts[Account name], chart_of_accounts[Code]) -> 8100 | E18: Income Tax Expense | F18: Closing Entry | H18: =_xlfn.XLOOKUP(E18, adjusted_trial_balance[Account Name], adjusted_trial_balance[Debit]) -> 45000
B19: 46053 | C19: J043 | D19: =_xlfn.XLOOKUP(E19, chart_of_accounts[Account name], chart_of_accounts[Code]) -> 2200 | E19: Retained Earnings | F19: Closing Entry | H19: {=SUM(-H4:H18, G4:G18)} -> 109266.67

Sheet post_closing_trial_balance
B2: Post-Closing Trial Balance
B3: Account Name | C3: Debit | D3: Credit
B4: =chart_of_accounts[[#This Row],[Account name]] -> Furniture & Fixtures | C4: {=IFERROR( IF( SUM( IFERROR(_xlfn._xlws.FILTER(general_journal[Debit], general_journal[Account Name] = B4), 0), IFERROR(_xlfn._xlws.FILTER(closing_entries[Debit], closing_entries[Account Name] = B4), 0) ) > SUM( IFERROR(_xlfn._xlws.FILTER(general_journal[Credit], general_journal[Account Name] = B4), 0), IFERROR(_xlfn._xlws.FILTER(closing_entries[Credit], closing_entries[Account Name] = B4), 0)), SUM( IFERROR(_xlfn._xlws.FILTER(general_journal[Debit], general_journal[Account Name] = B4), 0), IFERROR(_xlfn._xlws.FILTER(closing_entries[Debit], closing_entries[Account Name] = B4), 0) ) - SUM( IFERROR(_xlfn._xlws.FILTER(general_journal[Credit], general_journal[Account Name] = B4), 0), IFERROR(_xlfn._xlws.FILTER(closing_entries[Credit], closing_entries[Account Name] = B4), 0)), 0 ), 0)} -> 24000 | D4: {=IFERROR( IF( SUM( IFERROR(_xlfn._xlws.FILTER(general_journal[Debit], general_journal[Account Name] = B4), 0), IFERROR(_xlfn._xlws.FILTER(closing_entries[Debit], closing_entries[Account Name] = B4), 0) ) < SUM( IFERROR(_xlfn._xlws.FILTER(general_journal[Credit], general_journal[Account Name] = B4), 0), IFERROR(_xlfn._xlws.FILTER(closing_entries[Credit], closing_entries[Account Name] = B4), 0) ), SUM( IFERROR(_xlfn._xlws.FILTER(general_journal[Credit], general_journal[Account Name] = B4), 0), IFERROR(_xlfn._xlws.FILTER(closing_entries[Credit], closing_entries[Account Name] = B4), 0) ) - SUM( IFERROR(_xlfn._xlws.FILTER(general_journal[Debit], general_journal[Account Name] = B4), 0), IFERROR(_xlfn._xlws.FILTER(closing_entries[Debit], closing_entries[Account Name] = B4), 0) ), 0 ), 0)} -> 0
B5: =chart_of_accounts[[#This Row],[Account name]] -> Computer Equipment | C5: {=IFERROR( IF( SUM( IFERROR(_xlfn._xlws.FILTER(general_journal[Debit], general_journal[Account Name] = B5), 0), IFERROR(_xlfn._xlws.FILTER(closing_entries[Debit], closing_entries[Account Name] = B5), 0) ) > SUM( IFERROR(_xlfn._xlws.FILTER(general_journal[Credit], general_journal[Account Name] = B5), 0), IFERROR(_xlfn._xlws.FILTER(closing_entries[Credit], closing_entries[Account Name] = B5), 0)), SUM( IFERROR(_xlfn._xlws.FILTER(general_journal[Debit], general_journal[Account Name] = B5), 0), IFERROR(_xlfn._xlws.FILTER(closing_entries[Debit], closing_entries[Account Name] = B5), 0) ) - SUM( IFERROR(_xlfn._xlws.FILTER(general_journal[Credit], general_journal[Account Name] = B5), 0), IFERROR(_xlfn._xlws.FILTER(closing_entries[Credit], closing_entries[Account Name] = B5), 0)), 0 ), 0)} -> 30000 | D5: {=IFERROR( IF( SUM( IFERROR(_xlfn._xlws.FILTER(general_journal[Debit], general_journal[Account Name] = B5), 0), IFERROR(_xlfn._xlws.FILTER(closing_entries[Debit], closing_entries[Account Name] = B5), 0) ) < SUM( IFERROR(_xlfn._xlws.FILTER(general_journal[Credit], general_journal[Account Name] = B5), 0), IFERROR(_xlfn._xlws.FILTER(closing_entries[Credit], closing_entries[Account Name] = B5), 0) ), SUM( IFERROR(_xlfn._xlws.FILTER(general_journal[Credit], general_journal[Account Name] = B5), 0), IFERROR(_xlfn._xlws.FILTER(closing_entries[Credit], closing_entries[Account Name] = B5), 0) ) - SUM( IFERROR(_xlfn._xlws.FILTER(general_journal[Debit], general_journal[Account Name] = B5), 0), IFERROR(_xlfn._xlws.FILTER(closing_entries[Debit], closing_entries[Account Name] = B5), 0) ), 0 ), 0)} -> 0
B6: =chart_of_accounts[[#This Row],[Account name]] -> Accumulated Depreciation – PPE | C6: {=IFERROR( IF( SUM( IFERROR(_xlfn._xlws.FILTER(general_journal[Debit], general_journal[Account Name] = B6), 0), IFERROR(_xlfn._xlws.FILTER(closing_entries[Debit], closing_entries[Account Name] = B6), 0) ) > SUM( IFERROR(_xlfn._xlws.FILTER(general_journal[Credit], general_journal[Account Name] = B6), 0), IFERROR(_xlfn._xlws.FILTER(closing_entries[Credit], closing_entries[Account Name] = B6), 0)), SUM( IFERROR(_xlfn._xlws.FILTER(general_journal[Debit], general_journal[Account Name] = B6), 0), IFERROR(_xlfn._xlws.FILTER(closing_entries[Debit], closing_entries[Account Name] = B6), 0) ) - SUM( IFERROR(_xlfn._xlws.FILTER(general_journal[Credit], general_journal[Account Name] = B6), 0), IFERROR(_xlfn._xlws.FILTER(closing_entries[Credit], closing_entries[Account Name] = B6), 0)), 0 ), 0)} -> 0 | D6: {=IFERROR( IF( SUM( IFERROR(_xlfn._xlws.FILTER(general_journal[Debit], general_journal[Account Name] = B6), 0), IFERROR(_xlfn._xlws.FILTER(closing_entries[Debit], closing_entries[Account Name] = B6), 0) ) < SUM( IFERROR(_xlfn._xlws.FILTER(general_journal[Credit], general_journal[Account Name] = B6), 0), IFERROR(_xlfn._xlws.FILTER(closing_entries[Credit], closing_entries[Account Name] = B6), 0) ), SUM( IFERROR(_xlfn._xlws.FILTER(general_journal[Credit], general_journal[Account Name] = B6), 0), IFERROR(_xlfn._xlws.FILTER(closing_entries[Credit], closing_entries[Account Name] = B6), 0) ) - SUM( IFERROR(_xlfn._xlws.FILTER(general_journal[Debit], general_journal[Account Name] = B6), 0), IFERROR(_xlfn._xlws.FILTER(closing_entries[Debit], closing_entries[Account Name] = B6), 0) ), 0 ), 0)} -> 1233.3333
B7: =chart_of_accounts[[#This Row],[Account name]] -> Inventory | C7: {=IFERROR( IF( SUM( IFERROR(_xlfn._xlws.FILTER(general_journal[Debit], general_journal[Account Name] = B7), 0), IFERROR(_xlfn._xlws.FILTER(closing_entries[Debit], closing_entries[Account Name] = B7), 0) ) > SUM( IFERROR(_xlfn._xlws.FILTER(general_journal[Credit], general_journal[Account Name] = B7), 0), IFERROR(_xlfn._xlws.FILTER(closing_entries[Credit], closing_entries[Account Name] = B7), 0)), SUM( IFERROR(_xlfn._xlws.FILTER(general_journal[Debit], general_journal[Account Name] = B7), 0), IFERROR(_xlfn._xlws.FILTER(closing_entries[Debit], closing_entries[Account Name] = B7), 0) ) - SUM( IFERROR(_xlfn._xlws.FILTER(general_journal[Credit], general_journal[Account Name] = B7), 0), IFERROR(_xlfn._xlws.FILTER(closing_entries[Credit], closing_entries[Account Name] = B7), 0)), 0 ), 0)} -> 74500 | D7: {=IFERROR( IF( SUM( IFERROR(_xlfn._xlws.FILTER(general_journal[Debit], general_journal[Account Name] = B7), 0), IFERROR(_xlfn._xlws.FILTER(closing_entries[Debit], closing_entries[Account Name] = B7), 0) ) < SUM( IFERROR(_xlfn._xlws.FILTER(general_journal[Credit], general_journal[Account Name] = B7), 0), IFERROR(_xlfn._xlws.FILTER(closing_entries[Credit], closing_entries[Account Name] = B7), 0) ), SUM( IFERROR(_xlfn._xlws.FILTER(general_journal[Credit], general_journal[Account Name] = B7), 0), IFERROR(_xlfn._xlws.FILTER(closing_entries[Credit], closing_entries[Account Name] = B7), 0) ) - SUM( IFERROR(_xlfn._xlws.FILTER(general_journal[Debit], general_journal[Account Name] = B7), 0), IFERROR(_xlfn._xlws.FILTER(closing_entries[Debit], closing_entries[Account Name] = B7), 0) ), 0 ), 0)} -> 0
B8: =chart_of_accounts[[#This Row],[Account name]] -> Trade Receivables | C8: {=IFERROR( IF( SUM( IFERROR(_xlfn._xlws.FILTER(general_journal[Debit], general_journal[Account Name] = B8), 0), IFERROR(_xlfn._xlws.FILTER(closing_entries[Debit], closing_entries[Account Name] = B8), 0) ) > SUM( IFERROR(_xlfn._xlws.FILTER(general_journal[Credit], general_journal[Account Name] = B8), 0), IFERROR(_xlfn._xlws.FILTER(closing_entries[Credit], closing_entries[Account Name] = B8), 0)), SUM( IFERROR(_xlfn._xlws.FILTER(general_journal[Debit], general_journal[Account Name] = B8), 0), IFERROR(_xlfn._xlws.FILTER(closing_entries[Debit], closing_entries[Account Name] = B8), 0) ) - SUM( IFERROR(_xlfn._xlws.FILTER(general_journal[Credit], general_journal[Account Name] = B8), 0), IFERROR(_xlfn._xlws.FILTER(closing_entries[Credit], closing_entries[Account Name] = B8), 0)), 0 ), 0)} -> 223000 | D8: {=IFERROR( IF( SUM( IFERROR(_xlfn._xlws.FILTER(general_journal[Debit], general_journal[Account Name] = B8), 0), IFERROR(_xlfn._xlws.FILTER(closing_entries[Debit], closing_entries[Account Name] = B8), 0) ) < SUM( IFERROR(_xlfn._xlws.FILTER(general_journal[Credit], general_journal[Account Name] = B8), 0), IFERROR(_xlfn._xlws.FILTER(closing_entries[Credit], closing_entries[Account Name] = B8), 0) ), SUM( IFERROR(_xlfn._xlws.FILTER(general_journal[Credit], general_journal[Account Name] = B8), 0), IFERROR(_xlfn._xlws.FILTER(closing_entries[Credit], closing_entries[Account Name] = B8), 0) ) - SUM( IFERROR(_xlfn._xlws.FILTER(general_journal[Debit], general_journal[Account Name] = B8), 0), IFERROR(_xlfn._xlws.FILTER(closing_entries[Debit], closing_entries[Account Name] = B8), 0) ), 0 ), 0)} -> 0
B9: =chart_of_accounts[[#This Row],[Account name]] -> Prepayments | C9: {=IFERROR( IF( SUM( IFERROR(_xlfn._xlws.FILTER(general_journal[Debit], general_journal[Account Name] = B9), 0), IFERROR(_xlfn._xlws.FILTER(closing_entries[Debit], closing_entries[Account Name] = B9), 0) ) > SUM( IFERROR(_xlfn._xlws.FILTER(general_journal[Credit], general_journal[Account Name] = B9), 0), IFERROR(_xlfn._xlws.FILTER(closing_entries[Credit], closing_entries[Account Name] = B9), 0)), SUM( IFERROR(_xlfn._xlws.FILTER(general_journal[Debit], general_journal[Account Name] = B9), 0), IFERROR(_xlfn._xlws.FILTER(closing_entries[Debit], closing_entries[Account Name] = B9), 0) ) - SUM( IFERROR(_xlfn._xlws.FILTER(general_journal[Credit], general_journal[Account Name] = B9), 0), IFERROR(_xlfn._xlws.FILTER(closing_entries[Credit], closing_entries[Account Name] = B9), 0)), 0 ), 0)} -> 11000 | D9: {=IFERROR( IF( SUM( IFERROR(_xlfn._xlws.FILTER(general_journal[Debit], general_journal[Account Name] = B9), 0), IFERROR(_xlfn._xlws.FILTER(closing_entries[Debit], closing_entries[Account Name] = B9), 0) ) < SUM( IFERROR(_xlfn._xlws.FILTER(general_journal[Credit], general_journal[Account Name] = B9), 0), IFERROR(_xlfn._xlws.FILTER(closing_entries[Credit], closing_entries[Account Name] = B9), 0) ), SUM( IFERROR(_xlfn._xlws.FILTER(general_journal[Credit], general_journal[Account Name] = B9), 0), IFERROR(_xlfn._xlws.FILTER(closing_entries[Credit], closing_entries[Account Name] = B9), 0) ) - SUM( IFERROR(_xlfn._xlws.FILTER(general_journal[Debit], general_journal[Account Name] = B9), 0), IFERROR(_xlfn._xlws.FILTER(closing_entries[Debit], closing_entries[Account Name] = B9), 0) ), 0 ), 0)} -> 0
B10: =chart_of_accounts[[#This Row],[Account name]] -> Bank | C10: {=IFERROR( IF( SUM( IFERROR(_xlfn._xlws.FILTER(general_journal[Debit], general_journal[Account Name] = B10), 0), IFERROR(_xlfn._xlws.FILTER(closing_entries[Debit], closing_entries[Account Name] = B10), 0) ) > SUM( IFERROR(_xlfn._xlws.FILTER(general_journal[Credit], general_journal[Account Name] = B10), 0), IFERROR(_xlfn._xlws.FILTER(closing_entries[Credit], closing_entries[Account Name] = B10), 0)), SUM( IFERROR(_xlfn._xlws.FILTER(general_journal[Debit], general_journal[Account Name] = B10), 0), IFERROR(_xlfn._xlws.FILTER(closing_entries[Debit], closing_entries[Account Name] = B10), 0) ) - SUM( IFERROR(_xlfn._xlws.FILTER(general_journal[Credit], general_journal[Account Name] = B10), 0), IFERROR(_xlfn._xlws.FILTER(closing_entries[Credit], closing_entries[Account Name] = B10), 0)), 0 ), 0)} -> 746700 | D10: {=IFERROR( IF( SUM( IFERROR(_xlfn._xlws.FILTER(general_journal[Debit], general_journal[Account Name] = B10), 0), IFERROR(_xlfn._xlws.FILTER(closing_entries[Debit], closing_entries[Account Name] = B10), 0) ) < SUM( IFERROR(_xlfn._xlws.FILTER(general_journal[Credit], general_journal[Account Name] = B10), 0), IFERROR(_xlfn._xlws.FILTER(closing_entries[Credit], closing_entries[Account Name] = B10), 0) ), SUM( IFERROR(_xlfn._xlws.FILTER(general_journal[Credit], general_journal[Account Name] = B10), 0), IFERROR(_xlfn._xlws.FILTER(closing_entries[Credit], closing_entries[Account Name] = B10), 0) ) - SUM( IFERROR(_xlfn._xlws.FILTER(general_journal[Debit], general_journal[Account Name] = B10), 0), IFERROR(_xlfn._xlws.FILTER(closing_entries[Debit], closing_entries[Account Name] = B10), 0) ), 0 ), 0)} -> 0
B11: =chart_of_accounts[[#This Row],[Account name]] -> Ordinary Share Capital | C11: {=IFERROR( IF( SUM( IFERROR(_xlfn._xlws.FILTER(general_journal[Debit], general_journal[Account Name] = B11), 0), IFERROR(_xlfn._xlws.FILTER(closing_entries[Debit], closing_entries[Account Name] = B11), 0) ) > SUM( IFERROR(_xlfn._xlws.FILTER(general_journal[Credit], general_journal[Account Name] = B11), 0), IFERROR(_xlfn._xlws.FILTER(closing_entries[Credit], closing_entries[Account Name] = B11), 0)), SUM( IFERROR(_xlfn._xlws.FILTER(general_journal[Debit], general_journal[Account Name] = B11), 0), IFERROR(_xlfn._xlws.FILTER(closing_entries[Debit], closing_entries[Account Name] = B11), 0) ) - SUM( IFERROR(_xlfn._xlws.FILTER(general_journal[Credit], general_journal[Account Name] = B11), 0), IFERROR(_xlfn._xlws.FILTER(closing_entries[Credit], closing_entries[Account Name] = B11), 0)), 0 ), 0)} -> 0 | D11: {=IFERROR( IF( SUM( IFERROR(_xlfn._xlws.FILTER(general_journal[Debit], general_journal[Account Name] = B11), 0), IFERROR(_xlfn._xlws.FILTER(closing_entries[Debit], closing_entries[Account Name] = B11), 0) ) < SUM( IFERROR(_xlfn._xlws.FILTER(general_journal[Credit], general_journal[Account Name] = B11), 0), IFERROR(_xlfn._xlws.FILTER(closing_entries[Credit], closing_entries[Account Name] = B11), 0) ), SUM( IFERROR(_xlfn._xlws.FILTER(general_journal[Credit], general_journal[Account Name] = B11), 0), IFERROR(_xlfn._xlws.FILTER(closing_entries[Credit], closing_entries[Account Name] = B11), 0) ) - SUM( IFERROR(_xlfn._xlws.FILTER(general_journal[Debit], general_journal[Account Name] = B11), 0), IFERROR(_xlfn._xlws.FILTER(closing_entries[Debit], closing_entries[Account Name] = B11), 0) ), 0 ), 0)} -> 500000
B12: =chart_of_accounts[[#This Row],[Account name]] -> Retained Earnings | C12: {=IFERROR( IF( SUM( IFERROR(_xlfn._xlws.FILTER(general_journal[Debit], general_journal[Account Name] = B12), 0), IFERROR(_xlfn._xlws.FILTER(closing_entries[Debit], closing_entries[Account Name] = B12), 0) ) > SUM( IFERROR(_xlfn._xlws.FILTER(general_journal[Credit], general_journal[Account Name] = B12), 0), IFERROR(_xlfn._xlws.FILTER(closing_entries[Credit], closing_entries[Account Name] = B12), 0)), SUM( IFERROR(_xlfn._xlws.FILTER(general_journal[Debit], general_journal[Account Name] = B12), 0), IFERROR(_xlfn._xlws.FILTER(closing_entries[Debit], closing_entries[Account Name] = B12), 0) ) - SUM( IFERROR(_xlfn._xlws.FILTER(general_journal[Credit], general_journal[Account Name] = B12), 0), IFERROR(_xlfn._xlws.FILTER(closing_entries[Credit], closing_entries[Account Name] = B12), 0)), 0 ), 0)} -> 0 | D12: {=IFERROR( IF( SUM( IFERROR(_xlfn._xlws.FILTER(general_journal[Debit], general_journal[Account Name] = B12), 0), IFERROR(_xlfn._xlws.FILTER(closing_entries[Debit], closing_entries[Account Name] = B12), 0) ) < SUM( IFERROR(_xlfn._xlws.FILTER(general_journal[Credit], general_journal[Account Name] = B12), 0), IFERROR(_xlfn._xlws.FILTER(closing_entries[Credit], closing_entries[Account Name] = B12), 0) ), SUM( IFERROR(_xlfn._xlws.FILTER(general_journal[Credit], general_journal[Account Name] = B12), 0), IFERROR(_xlfn._xlws.FILTER(closing_entries[Credit], closing_entries[Account Name] = B12), 0) ) - SUM( IFERROR(_xlfn._xlws.FILTER(general_journal[Debit], general_journal[Account Name] = B12), 0), IFERROR(_xlfn._xlws.FILTER(closing_entries[Debit], closing_entries[Account Name] = B12), 0) ), 0 ), 0)} -> 109266.67
B13: =chart_of_accounts[[#This Row],[Account name]] -> Bank Loan | C13: {=IFERROR( IF( SUM( IFERROR(_xlfn._xlws.FILTER(general_journal[Debit], general_journal[Account Name] = B13), 0), IFERROR(_xlfn._xlws.FILTER(closing_entries[Debit], closing_entries[Account Name] = B13), 0) ) > SUM( IFERROR(_xlfn._xlws.FILTER(general_journal[Credit], general_journal[Account Name] = B13), 0), IFERROR(_xlfn._xlws.FILTER(closing_entries[Credit], closing_entries[Account Name] = B13), 0)), SUM( IFERROR(_xlfn._xlws.FILTER(general_journal[Debit], general_journal[Account Name] = B13), 0), IFERROR(_xlfn._xlws.FILTER(closing_entries[Debit], closing_entries[Account Name] = B13), 0) ) - SUM( IFERROR(_xlfn._xlws.FILTER(general_journal[Credit], general_journal[Account Name] = B13), 0), IFERROR(_xlfn._xlws.FILTER(closing_entries[Credit], closing_entries[Account Name] = B13), 0)), 0 ), 0)} -> 0 | D13: {=IFERROR( IF( SUM( IFERROR(_xlfn._xlws.FILTER(general_journal[Debit], general_journal[Account Name] = B13), 0), IFERROR(_xlfn._xlws.FILTER(closing_entries[Debit], closing_entries[Account Name] = B13), 0) ) < SUM( IFERROR(_xlfn._xlws.FILTER(general_journal[Credit], general_journal[Account Name] = B13), 0), IFERROR(_xlfn._xlws.FILTER(closing_entries[Credit], closing_entries[Account Name] = B13), 0) ), SUM( IFERROR(_xlfn._xlws.FILTER(general_journal[Credit], general_journal[Account Name] = B13), 0), IFERROR(_xlfn._xlws.FILTER(closing_entries[Credit], closing_entries[Account Name] = B13), 0) ) - SUM( IFERROR(_xlfn._xlws.FILTER(general_journal[Debit], general_journal[Account Name] = B13), 0), IFERROR(_xlfn._xlws.FILTER(closing_entries[Debit], closing_entries[Account Name] = B13), 0) ), 0 ), 0)} -> 149000
B14: =chart_of_accounts[[#This Row],[Account name]] -> Trade Payables | C14: {=IFERROR( IF( SUM( IFERROR(_xlfn._xlws.FILTER(general_journal[Debit], general_journal[Account Name] = B14), 0), IFERROR(_xlfn._xlws.FILTER(closing_entries[Debit], closing_entries[Account Name] = B14), 0) ) > SUM( IFERROR(_xlfn._xlws.FILTER(general_journal[Credit], general_journal[Account Name] = B14), 0), IFERROR(_xlfn._xlws.FILTER(closing_entries[Credit], closing_entries[Account Name] = B14), 0)), SUM( IFERROR(_xlfn._xlws.FILTER(general_journal[Debit], general_journal[Account Name] = B14), 0), IFERROR(_xlfn._xlws.FILTER(closing_entries[Debit], closing_entries[Account Name] = B14), 0) ) - SUM( IFERROR(_xlfn._xlws.FILTER(general_journal[Credit], general_journal[Account Name] = B14), 0), IFERROR(_xlfn._xlws.FILTER(closing_entries[Credit], closing_entries[Account Name] = B14), 0)), 0 ), 0)} -> 0 | D14: {=IFERROR( IF( SUM( IFERROR(_xlfn._xlws.FILTER(general_journal[Debit], general_journal[Account Name] = B14), 0), IFERROR(_xlfn._xlws.FILTER(closing_entries[Debit], closing_entries[Account Name] = B14), 0) ) < SUM( IFERROR(_xlfn._xlws.FILTER(general_journal[Credit], general_journal[Account Name] = B14), 0), IFERROR(_xlfn._xlws.FILTER(closing_entries[Credit], closing_entries[Account Name] = B14), 0) ), SUM( IFERROR(_xlfn._xlws.FILTER(general_journal[Credit], general_journal[Account Name] = B14), 0), IFERROR(_xlfn._xlws.FILTER(closing_entries[Credit], closing_entries[Account Name] = B14), 0) ) - SUM( IFERROR(_xlfn._xlws.FILTER(general_journal[Debit], general_journal[Account Name] = B14), 0), IFERROR(_xlfn._xlws.FILTER(closing_entries[Debit], closing_entries[Account Name] = B14), 0) ), 0 ), 0)} -> 271000
B15: =chart_of_accounts[[#This Row],[Account name]] -> Accrued Expenses | C15: {=IFERROR( IF( SUM( IFERROR(_xlfn._xlws.FILTER(general_journal[Debit], general_journal[Account Name] = B15), 0), IFERROR(_xlfn._xlws.FILTER(closing_entries[Debit], closing_entries[Account Name] = B15), 0) ) > SUM( IFERROR(_xlfn._xlws.FILTER(general_journal[Credit], general_journal[Account Name] = B15), 0), IFERROR(_xlfn._xlws.FILTER(closing_entries[Credit], closing_entries[Account Name] = B15), 0)), SUM( IFERROR(_xlfn._xlws.FILTER(general_journal[Debit], general_journal[Account Name] = B15), 0), IFERROR(_xlfn._xlws.FILTER(closing_entries[Debit], closing_entries[Account Name] = B15), 0) ) - SUM( IFERROR(_xlfn._xlws.FILTER(general_journal[Credit], general_journal[Account Name] = B15), 0), IFERROR(_xlfn._xlws.FILTER(closing_entries[Credit], closing_entries[Account Name] = B15), 0)), 0 ), 0)} -> 0 | D15: {=IFERROR( IF( SUM( IFERROR(_xlfn._xlws.FILTER(general_journal[Debit], general_journal[Account Name] = B15), 0), IFERROR(_xlfn._xlws.FILTER(closing_entries[Debit], closing_entries[Account Name] = B15), 0) ) < SUM( IFERROR(_xlfn._xlws.FILTER(general_journal[Credit], general_journal[Account Name] = B15), 0), IFERROR(_xlfn._xlws.FILTER(closing_entries[Credit], closing_entries[Account Name] = B15), 0) ), SUM( IFERROR(_xlfn._xlws.FILTER(general_journal[Credit], general_journal[Account Name] = B15), 0), IFERROR(_xlfn._xlws.FILTER(closing_entries[Credit], closing_entries[Account Name] = B15), 0) ) - SUM( IFERROR(_xlfn._xlws.FILTER(general_journal[Debit], general_journal[Account Name] = B15), 0), IFERROR(_xlfn._xlws.FILTER(closing_entries[Debit], closing_entries[Account Name] = B15), 0) ), 0 ), 0)} -> 3700
